Workbook

Sheet Resumen
A1: CONTROL DE COMPRAS POR TICKETS
A2: Ejercicio analizado: | B2: =YEAR(TODAY())
A3: Moneda: | B3: ARS
A5: ESTADO DEL EJERCICIO
A6: Gasto total del ejercicio | B6: =ROUND(SUMIFS(Compras!$L$2:$L$5000,Compras!$C$2:$C$5000,">="&DATE($B$2,1,1),Compras!$C$2:$C$5000,"<="&DATE($B$2,12,31)),2)
A7: Tickets registrados | B7: =COUNTIFS(Tickets!$B$2:$B$5000,">="&DATE($B$2,1,1),Tickets!$B$2:$B$5000,"<="&DATE($B$2,12,31))
A8: Lineas registradas | B8: =COUNTIFS(Compras!$C$2:$C$5000,">="&DATE($B$2,1,1),Compras!$C$2:$C$5000,"<="&DATE($B$2,12,31))
A9: Importe medio por ticket | B9: =IF($B$7=0,0,ROUND($B$6/$B$7,2))
A10: IVA incluido en las compras | B10: =ROUND(SUMIFS(Compras!$N$2:$N$5000,Compras!$C$2:$C$5000,">="&DATE($B$2,1,1),Compras!$C$2:$C$5000,"<="&DATE($B$2,12,31)),2)
A11: Tickets a revisar (no cuadran) | B11: =COUNTIFS(Tickets!$B$2:$B$5000,">="&DATE($B$2,1,1),Tickets!$B$2:$B$5000,"<="&DATE($B$2,12,31),Tickets!$G$2:$G$5000,"REVISAR")
A12: Posibles duplicados | B12: =COUNTIFS(Tickets!$B$2:$B$5000,">="&DATE($B$2,1,1),Tickets!$B$2:$B$5000,"<="&DATE($B$2,12,31),Tickets!$M$2:$M$5000,"DUPLICADO")
A14: GASTO POR MES
A15: Mes | B15: N. tickets | C15: Gasto | D15: % del ejercicio
A16: Enero | B16: =COUNTIFS(Tickets!$B$2:$B$5000,">="&DATE($B$2,1,1),Tickets!$B$2:$B$5000,"<="&EOMONTH(DATE($B$2,1,1),0)) | C16: =ROUND(SUMIFS(Compras!$L$2:$L$5000,Compras!$C$2:$C$5000,">="&DATE($B$2,1,1),Compras!$C$2:$C$5000,"<="&EOMONTH(DATE($B$2,1,1),0)),2) | D16: =IF($B$6=0,0,$C16/$B$6)
A17: Febrero | B17: =COUNTIFS(Tickets!$B$2:$B$5000,">="&DATE($B$2,2,1),Tickets!$B$2:$B$5000,"<="&EOMONTH(DATE($B$2,2,1),0)) | C17: =ROUND(SUMIFS(Compras!$L$2:$L$5000,Compras!$C$2:$C$5000,">="&DATE($B$2,2,1),Compras!$C$2:$C$5000,"<="&EOMONTH(DATE($B$2,2,1),0)),2) | D17: =IF($B$6=0,0,$C17/$B$6)
A18: Marzo | B18: =COUNTIFS(Tickets!$B$2:$B$5000,">="&DATE($B$2,3,1),Tickets!$B$2:$B$5000,"<="&EOMONTH(DATE($B$2,3,1),0)) | C18: =ROUND(SUMIFS(Compras!$L$2:$L$5000,Compras!$C$2:$C$5000,">="&DATE($B$2,3,1),Compras!$C$2:$C$5000,"<="&EOMONTH(DATE($B$2,3,1),0)),2) | D18: =IF($B$6=0,0,$C18/$B$6)
A19: Abril | B19: =COUNTIFS(Tickets!$B$2:$B$5000,">="&DATE($B$2,4,1),Tickets!$B$2:$B$5000,"<="&EOMONTH(DATE($B$2,4,1),0)) | C19: =ROUND(SUMIFS(Compras!$L$2:$L$5000,Compras!$C$2:$C$5000,">="&DATE($B$2,4,1),Compras!$C$2:$C$5000,"<="&EOMONTH(DATE($B$2,4,1),0)),2) | D19: =IF($B$6=0,0,$C19/$B$6)
A20: Mayo | B20: =COUNTIFS(Tickets!$B$2:$B$5000,">="&DATE($B$2,5,1),Tickets!$B$2:$B$5000,"<="&EOMONTH(DATE($B$2,5,1),0)) | C20: =ROUND(SUMIFS(Compras!$L$2:$L$5000,Compras!$C$2:$C$5000,">="&DATE($B$2,5,1),Compras!$C$2:$C$5000,"<="&EOMONTH(DATE($B$2,5,1),0)),2) | D20: =IF($B$6=0,0,$C20/$B$6)
A21: Junio | B21: =COUNTIFS(Tickets!$B$2:$B$5000,">="&DATE($B$2,6,1),Tickets!$B$2:$B$5000,"<="&EOMONTH(DATE($B$2,6,1),0)) | C21: =ROUND(SUMIFS(Compras!$L$2:$L$5000,Compras!$C$2:$C$5000,">="&DATE($B$2,6,1),Compras!$C$2:$C$5000,"<="&EOMONTH(DATE($B$2,6,1),0)),2) | D21: =IF($B$6=0,0,$C21/$B$6)
A22: Julio | B22: =COUNTIFS(Tickets!$B$2:$B$5000,">="&DATE($B$2,7,1),Tickets!$B$2:$B$5000,"<="&EOMONTH(DATE($B$2,7,1),0)) | C22: =ROUND(SUMIFS(Compras!$L$2:$L$5000,Compras!$C$2:$C$5000,">="&DATE($B$2,7,1),Compras!$C$2:$C$5000,"<="&EOMONTH(DATE($B$2,7,1),0)),2) | D22: =IF($B$6=0,0,$C22/$B$6)
A23: Agosto | B23: =COUNTIFS(Tickets!$B$2:$B$5000,">="&DATE($B$2,8,1),Tickets!$B$2:$B$5000,"<="&EOMONTH(DATE($B$2,8,1),0)) | C23: =ROUND(SUMIFS(Compras!$L$2:$L$5000,Compras!$C$2:$C$5000,">="&DATE($B$2,8,1),Compras!$C$2:$C$5000,"<="&EOMONTH(DATE($B$2,8,1),0)),2) | D23: =IF($B$6=0,0,$C23/$B$6)
A24: Septiembre | B24: =COUNTIFS(Tickets!$B$2:$B$5000,">="&DATE($B$2,9,1),Tickets!$B$2:$B$5000,"<="&EOMONTH(DATE($B$2,9,1),0)) | C24: =ROUND(SUMIFS(Compras!$L$2:$L$5000,Compras!$C$2:$C$5000,">="&DATE($B$2,9,1),Compras!$C$2:$C$5000,"<="&EOMONTH(DATE($B$2,9,1),0)),2) | D24: =IF($B$6=0,0,$C24/$B$6)
A25: Octubre | B25: =COUNTIFS(Tickets!$B$2:$B$5000,">="&DATE($B$2,10,1),Tickets!$B$2:$B$5000,"<="&EOMONTH(DATE($B$2,10,1),0)) | C25: =ROUND(SUMIFS(Compras!$L$2:$L$5000,Compras!$C$2:$C$5000,">="&DATE($B$2,10,1),Compras!$C$2:$C$5000,"<="&EOMONTH(DATE($B$2,10,1),0)),2) | D25: =IF($B$6=0,0,$C25/$B$6)
A26: Noviembre | B26: =COUNTIFS(Tickets!$B$2:$B$5000,">="&DATE($B$2,11,1),Tickets!$B$2:$B$5000,"<="&EOMONTH(DATE($B$2,11,1),0)) | C26: =ROUND(SUMIFS(Compras!$L$2:$L$5000,Compras!$C$2:$C$5000,">="&DATE($B$2,11,1),Compras!$C$2:$C$5000,"<="&EOMONTH(DATE($B$2,11,1),0)),2) | D26: =IF($B$6=0,0,$C26/$B$6)
A27: Diciembre | B27: =COUNTIFS(Tickets!$B$2:$B$5000,">="&DATE($B$2,12,1),Tickets!$B$2:$B$5000,"<="&EOMONTH(DATE($B$2,12,1),0)) | C27: =ROUND(SUMIFS(Compras!$L$2:$L$5000,Compras!$C$2:$C$5000,">="&DATE($B$2,12,1),Compras!$C$2:$C$5000,"<="&EOMONTH(DATE($B$2,12,1),0)),2) | D27: =IF($B$6=0,0,$C27/$B$6)
A28: TOTAL | B28: =SUM(B16:B27) | C28: =SUM(C16:C27) | D28: =SUM(D16:D27)
A30: GASTO POR CATEGORIA
A31: Categoria | B31: Gasto | C31: % del ejercicio | D31: N. lineas
A32: =IF(Listas!$A2="","",Listas!$A2) | B32: =IF($A32="","",ROUND(SUMIFS(Compras!$L$2:$L$5000,Compras!$F$2:$F$5000,$A32,Compras!$C$2:$C$5000,">="&DATE($B$2,1,1),Compras!$C$2:$C$5000,"<="&DATE($B$2,12,31)),2)) | C32: =IF(OR($A32="",$B$6=0),"",$B32/$B$6) | D32: =IF($A32="","",COUNTIFS(Compras!$F$2:$F$5000,$A32,Compras!$C$2:$C$5000,">="&DATE($B$2,1,1),Compras!$C$2:$C$5000,"<="&DATE($B$2,12,31)))
A33: =IF(Listas!$A3="","",Listas!$A3) | B33: =IF($A33="","",ROUND(SUMIFS(Compras!$L$2:$L$5000,Compras!$F$2:$F$5000,$A33,Compras!$C$2:$C$5000,">="&DATE($B$2,1,1),Compras!$C$2:$C$5000,"<="&DATE($B$2,12,31)),2)) | C33: =IF(OR($A33="",$B$6=0),"",$B33/$B$6) | D33: =IF($A33="","",COUNTIFS(Compras!$F$2:$F$5000,$A33,Compras!$C$2:$C$5000,">="&DATE($B$2,1,1),Compras!$C$2:$C$5000,"<="&DATE($B$2,12,31)))
A34: =IF(Listas!$A4="","",Listas!$A4) | B34: =IF($A34="","",ROUND(SUMIFS(Compras!$L$2:$L$5000,Compras!$F$2:$F$5000,$A34,Compras!$C$2:$C$5000,">="&DATE($B$2,1,1),Compras!$C$2:$C$5000,"<="&DATE($B$2,12,31)),2)) | C34: =IF(OR($A34="",$B$6=0),"",$B34/$B$6) | D34: =IF($A34="","",COUNTIFS(Compras!$F$2:$F$5000,$A34,Compras!$C$2:$C$5000,">="&DATE($B$2,1,1),Compras!$C$2:$C$5000,"<="&DATE($B$2,12,31)))
A35: =IF(Listas!$A5="","",Listas!$A5) | B35: =IF($A35="","",ROUND(SUMIFS(Compras!$L$2:$L$5000,Compras!$F$2:$F$5000,$A35,Compras!$C$2:$C$5000,">="&DATE($B$2,1,1),Compras!$C$2:$C$5000,"<="&DATE($B$2,12,31)),2)) | C35: =IF(OR($A35="",$B$6=0),"",$B35/$B$6) | D35: =IF($A35="","",COUNTIFS(Compras!$F$2:$F$5000,$A35,Compras!$C$2:$C$5000,">="&DATE($B$2,1,1),Compras!$C$2:$C$5000,"<="&DATE($B$2,12,31)))
A36: =IF(Listas!$A6="","",Listas!$A6) | B36: =IF($A36="","",ROUND(SUMIFS(Compras!$L$2:$L$5000,Compras!$F$2:$F$5000,$A36,Compras!$C$2:$C$5000,">="&DATE($B$2,1,1),Compras!$C$2:$C$5000,"<="&DATE($B$2,12,31)),2)) | C36: =IF(OR($A36="",$B$6=0),"",$B36/$B$6) | D36: =IF($A36="","",COUNTIFS(Compras!$F$2:$F$5000,$A36,Compras!$C$2:$C$5000,">="&DATE($B$2,1,1),Compras!$C$2:$C$5000,"<="&DATE($B$2,12,31)))
A37: =IF(Listas!$A7="","",Listas!$A7) | B37: =IF($A37="","",ROUND(SUMIFS(Compras!$L$2:$L$5000,Compras!$F$2:$F$5000,$A37,Compras!$C$2:$C$5000,">="&DATE($B$2,1,1),Compras!$C$2:$C$5000,"<="&DATE($B$2,12,31)),2)) | C37: =IF(OR($A37="",$B$6=0),"",$B37/$B$6) | D37: =IF($A37="","",COUNTIFS(Compras!$F$2:$F$5000,$A37,Compras!$C$2:$C$5000,">="&DATE($B$2,1,1),Compras!$C$2:$C$5000,"<="&DATE($B$2,12,31)))
A38: =IF(Listas!$A8="","",Listas!$A8) | B38: =IF($A38="","",ROUND(SUMIFS(Compras!$L$2:$L$5000,Compras!$F$2:$F$5000,$A38,Compras!$C$2:$C$5000,">="&DATE($B$2,1,1),Compras!$C$2:$C$5000,"<="&DATE($B$2,12,31)),2)) | C38: =IF(OR($A38="",$B$6=0),"",$B38/$B$6) | D38: =IF($A38="","",COUNTIFS(Compras!$F$2:$F$5000,$A38,Compras!$C$2:$C$5000,">="&DATE($B$2,1,1),Compras!$C$2:$C$5000,"<="&DATE($B$2,12,31)))
A39: =IF(Listas!$A9="","",Listas!$A9) | B39: =IF($A39="","",ROUND(SUMIFS(Compras!$L$2:$L$5000,Compras!$F$2:$F$5000,$A39,Compras!$C$2:$C$5000,">="&DATE($B$2,1,1),Compras!$C$2:$C$5000,"<="&DATE($B$2,12,31)),2)) | C39: =IF(OR($A39="",$B$6=0),"",$B39/$B$6) | D39: =IF($A39="","",COUNTIFS(Compras!$F$2:$F$5000,$A39,Compras!$C$2:$C$5000,">="&DATE($B$2,1,1),Compras!$C$2:$C$5000,"<="&DATE($B$2,12,31)))
A40: =IF(Listas!$A10="","",Listas!$A10) | B40: =IF($A40="","",ROUND(SUMIFS(Compras!$L$2:$L$5000,Compras!$F$2:$F$5000,$A40,Compras!$C$2:$C$5000,">="&DATE($B$2,1,1),Compras!$C$2:$C$5000,"<="&DATE($B$2,12,31)),2)) | C40: =IF(OR($A40="",$B$6=0),"",$B40/$B$6) | D40: =IF($A40="","",COUNTIFS(Compras!$F$2:$F$5000,$A40,Compras!$C$2:$C$5000,">="&DATE($B$2,1,1),Compras!$C$2:$C$5000,"<="&DATE($B$2,12,31)))
A41: =IF(Listas!$A11="","",Listas!$A11) | B41: =IF($A41="","",ROUND(SUMIFS(Compras!$L$2:$L$5000,Compras!$F$2:$F$5000,$A41,Compras!$C$2:$C$5000,">="&DATE($B$2,1,1),Compras!$C$2:$C$5000,"<="&DATE($B$2,12,31)),2)) | C41: =IF(OR($A41="",$B$6=0),"",$B41/$B$6) | D41: =IF($A41="","",COUNTIFS(Compras!$F$2:$F$5000,$A41,Compras!$C$2:$C$5000,">="&DATE($B$2,1,1),Compras!$C$2:$C$5000,"<="&DATE($B$2,12,31)))
A42: =IF(Listas!$A12="","",Listas!$A12) | B42: =IF($A42="","",ROUND(SUMIFS(Compras!$L$2:$L$5000,Compras!$F$2:$F$5000,$A42,Compras!$C$2:$C$5000,">="&DATE($B$2,1,1),Compras!$C$2:$C$5000,"<="&DATE($B$2,12,31)),2)) | C42: =IF(OR($A42="",$B$6=0),"",$B42/$B$6) | D42: =IF($A42="","",COUNTIFS(Compras!$F$2:$F$5000,$A42,Compras!$C$2:$C$5000,">="&DATE($B$2,1,1),Compras!$C$2:$C$5000,"<="&DATE($B$2,12,31)))
A43: =IF(Listas!$A13="","",Listas!$A13) | B43: =IF($A43="","",ROUND(SUMIFS(Compras!$L$2:$L$5000,Compras!$F$2:$F$5000,$A43,Compras!$C$2:$C$5000,">="&DATE($B$2,1,1),Compras!$C$2:$C$5000,"<="&DATE($B$2,12,31)),2)) | C43: =IF(OR($A43="",$B$6=0),"",$B43/$B$6) | D43: =IF($A43="","",COUNTIFS(Compras!$F$2:$F$5000,$A43,Compras!$C$2:$C$5000,">="&DATE($B$2,1,1),Compras!$C$2:$C$5000,"<="&DATE($B$2,12,31)))
...

Sheet Compras
A1: ID ticket | B1: Linea | C1: Fecha | D1: Mes | E1: Comercio | F1: Categoria | G1: Descripcion | H1: Cant. | I1: Unid. | J1: Precio unit. | K1: Descuento | L1: Importe | M1: IVA % | N1: IVA $ | O1: Forma de pago | P1: Moneda | Q1: N. ticket | R1: Archivo | S1: Notas | U1: Escribe o pega aqui una fila por producto del ticket. 'Mes', 'Importe' e 'IVA $' se calculan solos.
A2: TK-0001 | B2: 1 | C2: 46307 | D2: =IF($C2="","",YEAR($C2)&"-"&TEXT(MONTH($C2),"00")) | E2: Buenas Migas | F2: Panaderia | G2: Cafe Cortado Jarrita | H2: 1 | I2: ud | J2: 3000 | K2: 0 | L2: =IF($H2="","",ROUND($H2*$J2-N($K2),2)) | N2: =IF(OR($L2="",$M2=""),"",ROUND($L2-$L2/(1+$M2/100),2)) | O2: Tarjeta debito | P2: ARS | Q2: -
A3: TK-0001 | B3: 2 | C3: 46307 | D3: =IF($C3="","",YEAR($C3)&"-"&TEXT(MONTH($C3),"00")) | E3: Buenas Migas | F3: Panaderia | G3: Cafe Cortado Doble | H3: 2 | I3: ud | J3: 3500 | K3: 0 | L3: =IF($H3="","",ROUND($H3*$J3-N($K3),2)) | N3: =IF(OR($L3="",$M3=""),"",ROUND($L3-$L3/(1+$M3/100),2)) | O3: Tarjeta debito | P3: ARS | Q3: -
A4: TK-0001 | B4: 3 | C4: 46307 | D4: =IF($C4="","",YEAR($C4)&"-"&TEXT(MONTH($C4),"00")) | E4: Buenas Migas | F4: Panaderia | G4: Chocolatada | H4: 1 | I4: ud | J4: 3500 | K4: 0 | L4: =IF($H4="","",ROUND($H4*$J4-N($K4),2)) | N4: =IF(OR($L4="",$M4=""),"",ROUND($L4-$L4/(1+$M4/100),2)) | O4: Tarjeta debito | P4: ARS | Q4: -
A5: TK-0001 | B5: 4 | C5: 46307 | D5: =IF($C5="","",YEAR($C5)&"-"&TEXT(MONTH($C5),"00")) | E5: Buenas Migas | F5: Panaderia | G5: Medialuna de Jamón y Queso | H5: 1 | I5: ud | J5: 3000 | K5: 0 | L5: =IF($H5="","",ROUND($H5*$J5-N($K5),2)) | N5: =IF(OR($L5="",$M5=""),"",ROUND($L5-$L5/(1+$M5/100),2)) | O5: Tarjeta debito | P5: ARS | Q5: -
A6: TK-0001 | B6: 5 | C6: 46307 | D6: =IF($C6="","",YEAR($C6)&"-"&TEXT(MONTH($C6),"00")) | E6: Buenas Migas | F6: Panaderia | G6: Masas | H6: 1 | I6: ud | J6: 1920 | K6: 0 | L6: =IF($H6="","",ROUND($H6*$J6-N($K6),2)) | N6: =IF(OR($L6="",$M6=""),"",ROUND($L6-$L6/(1+$M6/100),2)) | O6: Tarjeta debito | P6: ARS | Q6: -
D7: =IF($C7="","",YEAR($C7)&"-"&TEXT(MONTH($C7),"00")) | L7: =IF($H7="","",ROUND($H7*$J7-N($K7),2)) | N7: =IF(OR($L7="",$M7=""),"",ROUND($L7-$L7/(1+$M7/100),2))
D8: =IF($C8="","",YEAR($C8)&"-"&TEXT(MONTH($C8),"00")) | L8: =IF($H8="","",ROUND($H8*$J8-N($K8),2)) | N8: =IF(OR($L8="",$M8=""),"",ROUND($L8-$L8/(1+$M8/100),2))
D9: =IF($C9="","",YEAR($C9)&"-"&TEXT(MONTH($C9),"00")) | L9: =IF($H9="","",ROUND($H9*$J9-N($K9),2)) | N9: =IF(OR($L9="",$M9=""),"",ROUND($L9-$L9/(1+$M9/100),2))
D10: =IF($C10="","",YEAR($C10)&"-"&TEXT(MONTH($C10),"00")) | L10: =IF($H10="","",ROUND($H10*$J10-N($K10),2)) | N10: =IF(OR($L10="",$M10=""),"",ROUND($L10-$L10/(1+$M10/100),2))
D11: =IF($C11="","",YEAR($C11)&"-"&TEXT(MONTH($C11),"00")) | L11: =IF($H11="","",ROUND($H11*$J11-N($K11),2)) | N11: =IF(OR($L11="",$M11=""),"",ROUND($L11-$L11/(1+$M11/100),2))
D12: =IF($C12="","",YEAR($C12)&"-"&TEXT(MONTH($C12),"00")) | L12: =IF($H12="","",ROUND($H12*$J12-N($K12),2)) | N12: =IF(OR($L12="",$M12=""),"",ROUND($L12-$L12/(1+$M12/100),2))
D13: =IF($C13="","",YEAR($C13)&"-"&TEXT(MONTH($C13),"00")) | L13: =IF($H13="","",ROUND($H13*$J13-N($K13),2)) | N13: =IF(OR($L13="",$M13=""),"",ROUND($L13-$L13/(1+$M13/100),2))
D14: =IF($C14="","",YEAR($C14)&"-"&TEXT(MONTH($C14),"00")) | L14: =IF($H14="","",ROUND($H14*$J14-N($K14),2)) | N14: =IF(OR($L14="",$M14=""),"",ROUND($L14-$L14/(1+$M14/100),2))
D15: =IF($C15="","",YEAR($C15)&"-"&TEXT(MONTH($C15),"00")) | L15: =IF($H15="","",ROUND($H15*$J15-N($K15),2)) | N15: =IF(OR($L15="",$M15=""),"",ROUND($L15-$L15/(1+$M15/100),2))
D16: =IF($C16="","",YEAR($C16)&"-"&TEXT(MONTH($C16),"00")) | L16: =IF($H16="","",ROUND($H16*$J16-N($K16),2)) | N16: =IF(OR($L16="",$M16=""),"",ROUND($L16-$L16/(1+$M16/100),2))
D17: =IF($C17="","",YEAR($C17)&"-"&TEXT(MONTH($C17),"00")) | L17: =IF($H17="","",ROUND($H17*$J17-N($K17),2)) | N17: =IF(OR($L17="",$M17=""),"",ROUND($L17-$L17/(1+$M17/100),2))
D18: =IF($C18="","",YEAR($C18)&"-"&TEXT(MONTH($C18),"00")) | L18: =IF($H18="","",ROUND($H18*$J18-N($K18),2)) | N18: =IF(OR($L18="",$M18=""),"",ROUND($L18-$L18/(1+$M18/100),2))
... D1000: =IF($C1000="","",YEAR($C1000)&"-"&TEXT(MONTH($C1000),"00")) | L1000: =IF($H1000="","",ROUND($H1000*$J1000-N($K1000),2)) | N1000: =IF(OR($L1000="",$M1000=""),"",ROUND($L1000-$L1000/(1+$M1000/100),2))

Sheet Tickets
A1: ID ticket | B1: Fecha | C1: Comercio | D1: Total ticket | E1: Total registrado | F1: Diferencia | G1: Estado | H1: N. ticket | I1: Forma de pago | J1: Moneda | K1: Archivo escaneado | L1: Notas | M1: Duplicado | O1: Una fila por ticket. 'Total ticket' = lo que dice el papel; 'Total registrado' = suma de sus lineas en Compras. Verde = cuadra, rojo = REVISAR o DUPLICADO.
A2: TK-0001 | B2: 46307 | C2: Buenas Migas | D2: 18420 | E2: =IF($A2="","",ROUND(SUMIFS(Compras!$L$2:$L$5000,Compras!$A$2:$A$5000,$A2),2)) | F2: =IF($A2="","",ROUND($D2-$E2,2)) | G2: =IF($A2="","",IF(ABS($F2)<=0.02,"OK","REVISAR")) | H2: - | I2: Tarjeta debito | J2: ARS | M2: =IF($A2="","",IF(COUNTIFS($B$2:$B$1000,$B2,$C$2:$C$1000,$C2,$D$2:$D$1000,$D2,$H$2:$H$1000,$H2)>1,"DUPLICADO",""))
E3: =IF($A3="","",ROUND(SUMIFS(Compras!$L$2:$L$5000,Compras!$A$2:$A$5000,$A3),2)) | F3: =IF($A3="","",ROUND($D3-$E3,2)) | G3: =IF($A3="","",IF(ABS($F3)<=0.02,"OK","REVISAR")) | M3: =IF($A3="","",IF(COUNTIFS($B$2:$B$1000,$B3,$C$2:$C$1000,$C3,$D$2:$D$1000,$D3,$H$2:$H$1000,$H3)>1,"DUPLICADO",""))
E4: =IF($A4="","",ROUND(SUMIFS(Compras!$L$2:$L$5000,Compras!$A$2:$A$5000,$A4),2)) | F4: =IF($A4="","",ROUND($D4-$E4,2)) | G4: =IF($A4="","",IF(ABS($F4)<=0.02,"OK","REVISAR")) | M4: =IF($A4="","",IF(COUNTIFS($B$2:$B$1000,$B4,$C$2:$C$1000,$C4,$D$2:$D$1000,$D4,$H$2:$H$1000,$H4)>1,"DUPLICADO",""))
E5: =IF($A5="","",ROUND(SUMIFS(Compras!$L$2:$L$5000,Compras!$A$2:$A$5000,$A5),2)) | F5: =IF($A5="","",ROUND($D5-$E5,2)) | G5: =IF($A5="","",IF(ABS($F5)<=0.02,"OK","REVISAR")) | M5: =IF($A5="","",IF(COUNTIFS($B$2:$B$1000,$B5,$C$2:$C$1000,$C5,$D$2:$D$1000,$D5,$H$2:$H$1000,$H5)>1,"DUPLICADO",""))
E6: =IF($A6="","",ROUND(SUMIFS(Compras!$L$2:$L$5000,Compras!$A$2:$A$5000,$A6),2)) | F6: =IF($A6="","",ROUND($D6-$E6,2)) | G6: =IF($A6="","",IF(ABS($F6)<=0.02,"OK","REVISAR")) | M6: =IF($A6="","",IF(COUNTIFS($B$2:$B$1000,$B6,$C$2:$C$1000,$C6,$D$2:$D$1000,$D6,$H$2:$H$1000,$H6)>1,"DUPLICADO",""))
E7: =IF($A7="","",ROUND(SUMIFS(Compras!$L$2:$L$5000,Compras!$A$2:$A$5000,$A7),2)) | F7: =IF($A7="","",ROUND($D7-$E7,2)) | G7: =IF($A7="","",IF(ABS($F7)<=0.02,"OK","REVISAR")) | M7: =IF($A7="","",IF(COUNTIFS($B$2:$B$1000,$B7,$C$2:$C$1000,$C7,$D$2:$D$1000,$D7,$H$2:$H$1000,$H7)>1,"DUPLICADO",""))
E8: =IF($A8="","",ROUND(SUMIFS(Compras!$L$2:$L$5000,Compras!$A$2:$A$5000,$A8),2)) | F8: =IF($A8="","",ROUND($D8-$E8,2)) | G8: =IF($A8="","",IF(ABS($F8)<=0.02,"OK","REVISAR")) | M8: =IF($A8="","",IF(COUNTIFS($B$2:$B$1000,$B8,$C$2:$C$1000,$C8,$D$2:$D$1000,$D8,$H$2:$H$1000,$H8)>1,"DUPLICADO",""))
E9: =IF($A9="","",ROUND(SUMIFS(Compras!$L$2:$L$5000,Compras!$A$2:$A$5000,$A9),2)) | F9: =IF($A9="","",ROUND($D9-$E9,2)) | G9: =IF($A9="","",IF(ABS($F9)<=0.02,"OK","REVISAR")) | M9: =IF($A9="","",IF(COUNTIFS($B$2:$B$1000,$B9,$C$2:$C$1000,$C9,$D$2:$D$1000,$D9,$H$2:$H$1000,$H9)>1,"DUPLICADO",""))
E10: =IF($A10="","",ROUND(SUMIFS(Compras!$L$2:$L$5000,Compras!$A$2:$A$5000,$A10),2)) | F10: =IF($A10="","",ROUND($D10-$E10,2)) | G10: =IF($A10="","",IF(ABS($F10)<=0.02,"OK","REVISAR")) | M10: =IF($A10="","",IF(COUNTIFS($B$2:$B$1000,$B10,$C$2:$C$1000,$C10,$D$2:$D$1000,$D10,$H$2:$H$1000,$H10)>1,"DUPLICADO",""))
E11: =IF($A11="","",ROUND(SUMIFS(Compras!$L$2:$L$5000,Compras!$A$2:$A$5000,$A11),2)) | F11: =IF($A11="","",ROUND($D11-$E11,2)) | G11: =IF($A11="","",IF(ABS($F11)<=0.02,"OK","REVISAR")) | M11: =IF($A11="","",IF(COUNTIFS($B$2:$B$1000,$B11,$C$2:$C$1000,$C11,$D$2:$D$1000,$D11,$H$2:$H$1000,$H11)>1,"DUPLICADO",""))
E12: =IF($A12="","",ROUND(SUMIFS(Compras!$L$2:$L$5000,Compras!$A$2:$A$5000,$A12),2)) | F12: =IF($A12="","",ROUND($D12-$E12,2)) | G12: =IF($A12="","",IF(ABS($F12)<=0.02,"OK","REVISAR")) | M12: =IF($A12="","",IF(COUNTIFS($B$2:$B$1000,$B12,$C$2:$C$1000,$C12,$D$2:$D$1000,$D12,$H$2:$H$1000,$H12)>1,"DUPLICADO",""))
E13: =IF($A13="","",ROUND(SUMIFS(Compras!$L$2:$L$5000,Compras!$A$2:$A$5000,$A13),2)) | F13: =IF($A13="","",ROUND($D13-$E13,2)) | G13: =IF($A13="","",IF(ABS($F13)<=0.02,"OK","REVISAR")) | M13: =IF($A13="","",IF(COUNTIFS($B$2:$B$1000,$B13,$C$2:$C$1000,$C13,$D$2:$D$1000,$D13,$H$2:$H$1000,$H13)>1,"DUPLICADO",""))
E14: =IF($A14="","",ROUND(SUMIFS(Compras!$L$2:$L$5000,Compras!$A$2:$A$5000,$A14),2)) | F14: =IF($A14="","",ROUND($D14-$E14,2)) | G14: =IF($A14="","",IF(ABS($F14)<=0.02,"OK","REVISAR")) | M14: =IF($A14="","",IF(COUNTIFS($B$2:$B$1000,$B14,$C$2:$C$1000,$C14,$D$2:$D$1000,$D14,$H$2:$H$1000,$H14)>1,"DUPLICADO",""))
... E400: =IF($A400="","",ROUND(SUMIFS(Compras!$L$2:$L$5000,Compras!$A$2:$A$5000,$A400),2)) | F400: =IF($A400="","",ROUND($D400-$E400,2)) | G400: =IF($A400="","",IF(ABS($F400)<=0.02,"OK","REVISAR")) | M400: =IF($A400="","",IF(COUNTIFS($B$2:$B$1000,$B400,$C$2:$C$1000,$C400,$D$2:$D$1000,$D400,$H$2:$H$1000,$H400)>1,"DUPLICADO",""))

Sheet Presupuesto
A1: PRESUPUESTO MENSUAL POR CATEGORIA
A2: Escribe tu presupuesto mensual (amarillo). El gasto se calcula sobre el mes en curso.
A4: Categoria | B4: Presupuesto mensual | C4: Gastado mes actual | D4: % ejecutado | E4: Disponible
A5: =IF(Listas!$A2="","",Listas!$A2) | C5: =IF($A5="","",ROUND(SUMIFS(Compras!$L$2:$L$5000,Compras!$F$2:$F$5000,$A5,Compras!$C$2:$C$5000,">="&EOMONTH(TODAY(),-1)+1,Compras!$C$2:$C$5000,"<="&EOMONTH(TODAY(),0)),2)) | D5: =IF(OR($A5="",N($B5)=0),"",$C5/$B5) | E5: =IF($A5="","",ROUND(N($B5)-$C5,2))
A6: =IF(Listas!$A3="","",Listas!$A3) | C6: =IF($A6="","",ROUND(SUMIFS(Compras!$L$2:$L$5000,Compras!$F$2:$F$5000,$A6,Compras!$C$2:$C$5000,">="&EOMONTH(TODAY(),-1)+1,Compras!$C$2:$C$5000,"<="&EOMONTH(TODAY(),0)),2)) | D6: =IF(OR($A6="",N($B6)=0),"",$C6/$B6) | E6: =IF($A6="","",ROUND(N($B6)-$C6,2))
A7: =IF(Listas!$A4="","",Listas!$A4) | C7: =IF($A7="","",ROUND(SUMIFS(Compras!$L$2:$L$5000,Compras!$F$2:$F$5000,$A7,Compras!$C$2:$C$5000,">="&EOMONTH(TODAY(),-1)+1,Compras!$C$2:$C$5000,"<="&EOMONTH(TODAY(),0)),2)) | D7: =IF(OR($A7="",N($B7)=0),"",$C7/$B7) | E7: =IF($A7="","",ROUND(N($B7)-$C7,2))
A8: =IF(Listas!$A5="","",Listas!$A5) | C8: =IF($A8="","",ROUND(SUMIFS(Compras!$L$2:$L$5000,Compras!$F$2:$F$5000,$A8,Compras!$C$2:$C$5000,">="&EOMONTH(TODAY(),-1)+1,Compras!$C$2:$C$5000,"<="&EOMONTH(TODAY(),0)),2)) | D8: =IF(OR($A8="",N($B8)=0),"",$C8/$B8) | E8: =IF($A8="","",ROUND(N($B8)-$C8,2))
A9: =IF(Listas!$A6="","",Listas!$A6) | C9: =IF($A9="","",ROUND(SUMIFS(Compras!$L$2:$L$5000,Compras!$F$2:$F$5000,$A9,Compras!$C$2:$C$5000,">="&EOMONTH(TODAY(),-1)+1,Compras!$C$2:$C$5000,"<="&EOMONTH(TODAY(),0)),2)) | D9: =IF(OR($A9="",N($B9)=0),"",$C9/$B9) | E9: =IF($A9="","",ROUND(N($B9)-$C9,2))
A10: =IF(Listas!$A7="","",Listas!$A7) | C10: =IF($A10="","",ROUND(SUMIFS(Compras!$L$2:$L$5000,Compras!$F$2:$F$5000,$A10,Compras!$C$2:$C$5000,">="&EOMONTH(TODAY(),-1)+1,Compras!$C$2:$C$5000,"<="&EOMONTH(TODAY(),0)),2)) | D10: =IF(OR($A10="",N($B10)=0),"",$C10/$B10) | E10: =IF($A10="","",ROUND(N($B10)-$C10,2))
A11: =IF(Listas!$A8="","",Listas!$A8) | C11: =IF($A11="","",ROUND(SUMIFS(Compras!$L$2:$L$5000,Compras!$F$2:$F$5000,$A11,Compras!$C$2:$C$5000,">="&EOMONTH(TODAY(),-1)+1,Compras!$C$2:$C$5000,"<="&EOMONTH(TODAY(),0)),2)) | D11: =IF(OR($A11="",N($B11)=0),"",$C11/$B11) | E11: =IF($A11="","",ROUND(N($B11)-$C11,2))
A12: =IF(Listas!$A9="","",Listas!$A9) | C12: =IF($A12="","",ROUND(SUMIFS(Compras!$L$2:$L$5000,Compras!$F$2:$F$5000,$A12,Compras!$C$2:$C$5000,">="&EOMONTH(TODAY(),-1)+1,Compras!$C$2:$C$5000,"<="&EOMONTH(TODAY(),0)),2)) | D12: =IF(OR($A12="",N($B12)=0),"",$C12/$B12) | E12: =IF($A12="","",ROUND(N($B12)-$C12,2))
A13: =IF(Listas!$A10="","",Listas!$A10) | C13: =IF($A13="","",ROUND(SUMIFS(Compras!$L$2:$L$5000,Compras!$F$2:$F$5000,$A13,Compras!$C$2:$C$5000,">="&EOMONTH(TODAY(),-1)+1,Compras!$C$2:$C$5000,"<="&EOMONTH(TODAY(),0)),2)) | D13: =IF(OR($A13="",N($B13)=0),"",$C13/$B13) | E13: =IF($A13="","",ROUND(N($B13)-$C13,2))
A14: =IF(Listas!$A11="","",Listas!$A11) | C14: =IF($A14="","",ROUND(SUMIFS(Compras!$L$2:$L$5000,Compras!$F$2:$F$5000,$A14,Compras!$C$2:$C$5000,">="&EOMONTH(TODAY(),-1)+1,Compras!$C$2:$C$5000,"<="&EOMONTH(TODAY(),0)),2)) | D14: =IF(OR($A14="",N($B14)=0),"",$C14/$B14) | E14: =IF($A14="","",ROUND(N($B14)-$C14,2))
A15: =IF(Listas!$A12="","",Listas!$A12) | C15: =IF($A15="","",ROUND(SUMIFS(Compras!$L$2:$L$5000,Compras!$F$2:$F$5000,$A15,Compras!$C$2:$C$5000,">="&EOMONTH(TODAY(),-1)+1,Compras!$C$2:$C$5000,"<="&EOMONTH(TODAY(),0)),2)) | D15: =IF(OR($A15="",N($B15)=0),"",$C15/$B15) | E15: =IF($A15="","",ROUND(N($B15)-$C15,2))
A16: =IF(Listas!$A13="","",Listas!$A13) | C16: =IF($A16="","",ROUND(SUMIFS(Compras!$L$2:$L$5000,Compras!$F$2:$F$5000,$A16,Compras!$C$2:$C$5000,">="&EOMONTH(TODAY(),-1)+1,Compras!$C$2:$C$5000,"<="&EOMONTH(TODAY(),0)),2)) | D16: =IF(OR($A16="",N($B16)=0),"",$C16/$B16) | E16: =IF($A16="","",ROUND(N($B16)-$C16,2))
... A28: =IF(Listas!$A25="","",Listas!$A25) | C28: =IF($A28="","",ROUND(SUMIFS(Compras!$L$2:$L$5000,Compras!$F$2:$F$5000,$A28,Compras!$C$2:$C$5000,">="&EOMONTH(TODAY(),-1)+1,Compras!$C$2:$C$5000,"<="&EOMONTH(TODAY(),0)),2)) | D28: =IF(OR($A28="",N($B28)=0),"",$C28/$B28) | E28: =IF($A28="","",ROUND(N($B28)-$C28,2))
A29: TOTAL | B29: =SUM(B5:B28) | C29: =SUM(C5:C28) | E29: =SUM(E5:E28)

Sheet Listas
A1: Categorias | B1: Formas de pago | C1: Unidades | D1: Moneda | F1: Listas editables. Capacidad maxima: 24 categorias, 14 formas de pago, 10 unidades. Si anades una categoria nueva, aparece sola en el Resumen y el Presupuesto.
A2: Supermercado | B2: Efectivo | C2: ud | D2: ARS
A3: Almacen y bebidas | B3: Tarjeta debito | C3: kg | D3: USD
A4: Carniceria | B4: Tarjeta credito | C4: g | D4: EUR
A5: Verduleria y frutas | B5: Transferencia | C5: L | D5: BRL
A6: Panaderia | B6: Billetera virtual | C6: ml | D6: UYU
A7: Restaurantes y bares | B7: QR / Mercado Pago | C7: m | D7: CLP
A8: Transporte y combustible | B8: Cheque | C8: m2 | D8: PYG
A9: Hogar y ferreteria | B9: Debito automatico | C9: caja | D9: BOB
A10: Ropa y calzado | B10: Cuenta corriente | C10: pack | D10: MXN
A11: Salud y farmacia | B11: Crypto | C11: servicio | D11: COP
A12: Tecnologia | B12: Vale / cupon | D12: PEN
A13: Ocio y entretenimiento | B13: Otro
A14: Servicios y suministros
A15: Educacion
A16: Mascotas
A17: Cuidado personal
A18: Regalos
A19: Impuestos y tasas
A20: Viajes
A21: Otros
